(.venv) PS C:\Users\client\Desktop\RICOZ87\crypto-analysis-dashboard-main> python main.py
Traceback (most recent call last):
  File "C:\Users\client\Desktop\RICOZ87\crypto-analysis-dashboard-main\.venv\Lib\site-packages\sqlalchemy\engine\base.py", line 143, in __init__
    self._dbapi_connection = engine.raw_connection()
                             ^^^^^^^^^^^^^^^^^^^^^^^
  File "C:\Users\client\Desktop\RICOZ87\crypto-analysis-dashboard-main\.venv\Lib\site-packages\sqlalchemy\engine\base.py", line 3295, in raw_connection
    return self.pool.connect()
           ^^^^^^^^^^^^^^^^^^^
  File "C:\Users\client\Desktop\RICOZ87\crypto-analysis-dashboard-main\.venv\Lib\site-packages\sqlalchemy\pool\base.py", line 447, in connect
    return _ConnectionFairy._checkout(self)
           ^^^^^^^^^^^^^^^^^^^^^^^^^^^^^^^^
  File "C:\Users\client\Desktop\RICOZ87\crypto-analysis-dashboard-main\.venv\Lib\site-packages\sqlalchemy\pool\base.py", line 1264, in _checkout
    fairy = _ConnectionRecord.checkout(pool)
            ^^^^^^^^^^^^^^^^^^^^^^^^^^^^^^^^
  File "C:\Users\client\Desktop\RICOZ87\crypto-analysis-dashboard-main\.venv\Lib\site-packages\sqlalchemy\pool\base.py", line 711, in checkout
    rec = pool._do_get()
          ^^^^^^^^^^^^^^
  File "C:\Users\client\Desktop\RICOZ87\crypto-analysis-dashboard-main\.venv\Lib\site-packages\sqlalchemy\pool\impl.py", line 177, in _do_get
    with util.safe_reraise():
  File "C:\Users\client\Desktop\RICOZ87\crypto-analysis-dashboard-main\.venv\Lib\site-packages\sqlalchemy\util\langhelpers.py", line 224, in __exit__
    raise exc_value.with_traceback(exc_tb)
  File "C:\Users\client\Desktop\RICOZ87\crypto-analysis-dashboard-main\.venv\Lib\site-packages\sqlalchemy\pool\impl.py", line 175, in _do_get
    return self._create_connection()
           ^^^^^^^^^^^^^^^^^^^^^^^^^
  File "C:\Users\client\Desktop\RICOZ87\crypto-analysis-dashboard-main\.venv\Lib\site-packages\sqlalchemy\pool\base.py", line 388, in _create_connection
    return _ConnectionRecord(self)
           ^^^^^^^^^^^^^^^^^^^^^^^
  File "C:\Users\client\Desktop\RICOZ87\crypto-analysis-dashboard-main\.venv\Lib\site-packages\sqlalchemy\pool\base.py", line 673, in __init__
    self.__connect()
  File "C:\Users\client\Desktop\RICOZ87\crypto-analysis-dashboard-main\.venv\Lib\site-packages\sqlalchemy\pool\base.py", line 899, in __connect
    with util.safe_reraise():
  File "C:\Users\client\Desktop\RICOZ87\crypto-analysis-dashboard-main\.venv\Lib\site-packages\sqlalchemy\util\langhelpers.py", line 224, in __exit__
    raise exc_value.with_traceback(exc_tb)
  File "C:\Users\client\Desktop\RICOZ87\crypto-analysis-dashboard-main\.venv\Lib\site-packages\sqlalchemy\pool\base.py", line 895, in __connect
    self.dbapi_connection = connection = pool._invoke_creator(self)
                                         ^^^^^^^^^^^^^^^^^^^^^^^^^^
  File "C:\Users\client\Desktop\RICOZ87\crypto-analysis-dashboard-main\.venv\Lib\site-packages\sqlalchemy\engine\create.py", line 646, in connect
    return dialect.connect(*cargs, **cparams)
           ^^^^^^^^^^^^^^^^^^^^^^^^^^^^^^^^^^
  File "C:\Users\client\Desktop\RICOZ87\crypto-analysis-dashboard-main\.venv\Lib\site-packages\sqlalchemy\engine\default.py", line 626, in connect
    return self.loaded_dbapi.connect(*cargs, **cparams)  # type: ignore[no-any-return]  # NOQA: E501
           ^^^^^^^^^^^^^^^^^^^^^^^^^^^^^^^^^^^^^^^^^^^^
  File "C:\Users\client\Desktop\RICOZ87\crypto-analysis-dashboard-main\.venv\Lib\site-packages\psycopg2\__init__.py", line 122, in connect
    conn = _connect(dsn, connection_factory=connection_factory, **kwasync)
           ^^^^^^^^^^^^^^^^^^^^^^^^^^^^^^^^^^^^^^^^^^^^^^^^^^^^^^^^^^^^^^^
psycopg2.OperationalError: could not translate host name "..." to address: No such host is known.


The above exception was the direct cause of the following exception:

Traceback (most recent call last):
  File "C:\Users\client\Desktop\RICOZ87\crypto-analysis-dashboard-main\main.py", line 1, in <module>
    from app import app  # noqa: F401
    ^^^^^^^^^^^^^^^^^^^
  File "C:\Users\client\Desktop\RICOZ87\crypto-analysis-dashboard-main\app.py", line 43, in <module>
    db.create_all()
  File "C:\Users\client\Desktop\RICOZ87\crypto-analysis-dashboard-main\.venv\Lib\site-packages\flask_sqlalchemy\extension.py", line 900, in create_all
    self._call_for_binds(bind_key, "create_all")
  File "C:\Users\client\Desktop\RICOZ87\crypto-analysis-dashboard-main\.venv\Lib\site-packages\flask_sqlalchemy\extension.py", line 881, in _call_for_binds
    getattr(metadata, op_name)(bind=engine)
  File "C:\Users\client\Desktop\RICOZ87\crypto-analysis-dashboard-main\.venv\Lib\site-packages\sqlalchemy\sql\schema.py", line 5924, in create_all
    bind._run_ddl_visitor(
  File "C:\Users\client\Desktop\RICOZ87\crypto-analysis-dashboard-main\.venv\Lib\site-packages\sqlalchemy\engine\base.py", line 3245, in _run_ddl_visitor
    with self.begin() as conn:
  File "C:\Users\client\AppData\Local\Programs\Python\Python311\Lib\contextlib.py", line 137, in __enter__
    return next(self.gen)
           ^^^^^^^^^^^^^^
  File "C:\Users\client\Desktop\RICOZ87\crypto-analysis-dashboard-main\.venv\Lib\site-packages\sqlalchemy\engine\base.py", line 3235, in begin
    with self.connect() as conn:
         ^^^^^^^^^^^^^^
  File "C:\Users\client\Desktop\RICOZ87\crypto-analysis-dashboard-main\.venv\Lib\site-packages\sqlalchemy\engine\base.py", line 3271, in connect
    return self._connection_cls(self)
           ^^^^^^^^^^^^^^^^^^^^^^^^^^
  File "C:\Users\client\Desktop\RICOZ87\crypto-analysis-dashboard-main\.venv\Lib\site-packages\sqlalchemy\engine\base.py", line 145, in __init__
    Connection._handle_dbapi_exception_noconnection(
  File "C:\Users\client\Desktop\RICOZ87\crypto-analysis-dashboard-main\.venv\Lib\site-packages\sqlalchemy\engine\base.py", line 2434, in _handle_dbapi_exception_noconnection
    raise sqlalchemy_exception.with_traceback(exc_info[2]) from e
  File "C:\Users\client\Desktop\RICOZ87\crypto-analysis-dashboard-main\.venv\Lib\site-packages\sqlalchemy\engine\base.py", line 143, in __init__
    self._dbapi_connection = engine.raw_connection()
                             ^^^^^^^^^^^^^^^^^^^^^^^
  File "C:\Users\client\Desktop\RICOZ87\crypto-analysis-dashboard-main\.venv\Lib\site-packages\sqlalchemy\engine\base.py", line 3295, in raw_connection
    return self.pool.connect()
           ^^^^^^^^^^^^^^^^^^^
  File "C:\Users\client\Desktop\RICOZ87\crypto-analysis-dashboard-main\.venv\Lib\site-packages\sqlalchemy\pool\base.py", line 447, in connect
    return _ConnectionFairy._checkout(self)
           ^^^^^^^^^^^^^^^^^^^^^^^^^^^^^^^^
  File "C:\Users\client\Desktop\RICOZ87\crypto-analysis-dashboard-main\.venv\Lib\site-packages\sqlalchemy\pool\base.py", line 1264, in _checkout
    fairy = _ConnectionRecord.checkout(pool)
            ^^^^^^^^^^^^^^^^^^^^^^^^^^^^^^^^
  File "C:\Users\client\Desktop\RICOZ87\crypto-analysis-dashboard-main\.venv\Lib\site-packages\sqlalchemy\pool\base.py", line 711, in checkout
    rec = pool._do_get()
          ^^^^^^^^^^^^^^
  File "C:\Users\client\Desktop\RICOZ87\crypto-analysis-dashboard-main\.venv\Lib\site-packages\sqlalchemy\pool\impl.py", line 177, in _do_get
    with util.safe_reraise():
  File "C:\Users\client\Desktop\RICOZ87\crypto-analysis-dashboard-main\.venv\Lib\site-packages\sqlalchemy\util\langhelpers.py", line 224, in __exit__
    raise exc_value.with_traceback(exc_tb)
  File "C:\Users\client\Desktop\RICOZ87\crypto-analysis-dashboard-main\.venv\Lib\site-packages\sqlalchemy\pool\impl.py", line 175, in _do_get
    return self._create_connection()
           ^^^^^^^^^^^^^^^^^^^^^^^^^
  File "C:\Users\client\Desktop\RICOZ87\crypto-analysis-dashboard-main\.venv\Lib\site-packages\sqlalchemy\pool\base.py", line 388, in _create_connection
    return _ConnectionRecord(self)
           ^^^^^^^^^^^^^^^^^^^^^^^
  File "C:\Users\client\Desktop\RICOZ87\crypto-analysis-dashboard-main\.venv\Lib\site-packages\sqlalchemy\pool\base.py", line 673, in __init__
    self.__connect()
  File "C:\Users\client\Desktop\RICOZ87\crypto-analysis-dashboard-main\.venv\Lib\site-packages\sqlalchemy\pool\base.py", line 899, in __connect
    with util.safe_reraise():
  File "C:\Users\client\Desktop\RICOZ87\crypto-analysis-dashboard-main\.venv\Lib\site-packages\sqlalchemy\util\langhelpers.py", line 224, in __exit__
    raise exc_value.with_traceback(exc_tb)
  File "C:\Users\client\Desktop\RICOZ87\crypto-analysis-dashboard-main\.venv\Lib\site-packages\sqlalchemy\pool\base.py", line 895, in __connect
    self.dbapi_connection = connection = pool._invoke_creator(self)
                                         ^^^^^^^^^^^^^^^^^^^^^^^^^^
  File "C:\Users\client\Desktop\RICOZ87\crypto-analysis-dashboard-main\.venv\Lib\site-packages\sqlalchemy\engine\create.py", line 646, in connect
    return dialect.connect(*cargs, **cparams)
           ^^^^^^^^^^^^^^^^^^^^^^^^^^^^^^^^^^
  File "C:\Users\client\Desktop\RICOZ87\crypto-analysis-dashboard-main\.venv\Lib\site-packages\sqlalchemy\engine\default.py", line 626, in connect
    return self.loaded_dbapi.connect(*cargs, **cparams)  # type: ignore[no-any-return]  # NOQA: E501
           ^^^^^^^^^^^^^^^^^^^^^^^^^^^^^^^^^^^^^^^^^^^^
  File "C:\Users\client\Desktop\RICOZ87\crypto-analysis-dashboard-main\.venv\Lib\site-packages\psycopg2\__init__.py", line 122, in connect
    conn = _connect(dsn, connection_factory=connection_factory, **kwasync)
           ^^^^^^^^^^^^^^^^^^^^^^^^^^^^^^^^^^^^^^^^^^^^^^^^^^^^^^^^^^^^^^^
sqlalchemy.exc.OperationalError: (psycopg2.OperationalError) could not translate host name "..." to address: No such host is known.

(Background on this error at: https://sqlalche.me/e/20/e3q8)
(.venv) PS C:\Users\client\Desktop\RICOZ87\crypto-analysis-dashboard-main> 